use std::fmt;
use std::error::Error as StdError;

#[derive(Debug)]
pub enum DataProcessingError {
    SourceError {
        source: String,
        kind: SourceErrorKind,
        inner: Option<Box<dyn StdError + Send + Sync>>,
    },
    ProcessingError {
        stage: ProcessingStage,
        message: String,
        cause: Option<Box<DataProcessingError>>,
    },
    ValidationError {
        field: String,
        expected: String,
        actual: String,
    },
    StorageError {
        operation: StorageOperation,
        path: Option<String>,
        inner: Box<dyn StdError + Send + Sync>,
    },
    ConfigurationError {
        parameter: String,
        message: String,
    },
    TimeoutError {
        operation: String,
        timeout_ms: u64,
    },
    NetworkError {
        url: String,
        status_code: Option<u16>,
        message: String,
    },
}

#[derive(Debug, Clone)]
pub enum SourceErrorKind {
    ConnectionFailed,
    AuthenticationFailed,
    PermissionDenied,
    ResourceNotFound,
    ServiceUnavailable,
}

#[derive(Debug, Clone)]
pub enum ProcessingStage {
    Initialization,
    DataFetch,
    Validation,
    Transformation,
    Aggregation,
    Finalization,
}

#[derive(Debug, Clone)]
pub enum StorageOperation {
    Read,
    Write,
    Delete,
    Update,
    Create,
}

impl fmt::Display for DataProcessingError {
    fn fmt(&self, f: &mut fmt::Formatter<'_>) -> fmt::Result {
        match self {
            DataProcessingError::SourceError { source, kind, .. } => {
                write!(f, "Source error in {}: {:?}", source, kind)
            }
            DataProcessingError::ProcessingError { stage, message, .. } => {
                write!(f, "Processing error at {:?}: {}", stage, message)
            }
            DataProcessingError::ValidationError { field, expected, actual } => {
                write!(f, "Validation error for field '{}': expected '{}', got '{}'", field, expected, actual)
            }
            DataProcessingError::StorageError { operation, path, .. } => {
                write!(f, "Storage error during {:?}{}", operation, 
                    path.as_ref().map_or(String::new(), |p| format!(" at '{}'", p)))
            }
            DataProcessingError::ConfigurationError { parameter, message } => {
                write!(f, "Configuration error for '{}': {}", parameter, message)
            }
            DataProcessingError::TimeoutError { operation, timeout_ms } => {
                write!(f, "Operation '{}' timed out after {}ms", operation, timeout_ms)
            }
            DataProcessingError::NetworkError { url, status_code, message } => {
                write!(f, "Network error for '{}'{}: {}", 
                    url, 
                    status_code.map_or(String::new(), |c| format!(" (status: {})", c)), 
                    message)
            }
        }
    }
}

impl StdError for DataProcessingError {
    fn source(&self) -> Option<&(dyn StdError + 'static)> {
        match self {
            DataProcessingError::SourceError { inner: Some(inner), .. } => {
                Some(&**inner as &(dyn StdError + 'static))
            }
            DataProcessingError::ProcessingError { cause: Some(cause), .. } => {
                Some(cause as &(dyn StdError + 'static))
            }
            DataProcessingError::StorageError { inner, .. } => {
                Some(&**inner as &(dyn StdError + 'static))
            }
            _ => None,
        }
    }
}

pub type Result<T> = std::result::Result<T, DataProcessingError>;

impl DataProcessingError {
    pub fn source_error(source: impl Into<String>, kind: SourceErrorKind) -> Self {
        unimplemented!("Create source error")
    }
    
    pub fn with_inner_error<E>(mut self, error: E) -> Self 
    where
        E: StdError + Send + Sync + 'static,
    {
        unimplemented!("Add inner error")
    }
    
    pub fn processing_error(stage: ProcessingStage, message: impl Into<String>) -> Self {
        unimplemented!("Create processing error")
    }
    
    pub fn with_cause(mut self, cause: DataProcessingError) -> Self {
        unimplemented!("Add cause error")
    }
    
    pub fn validation_error(
        field: impl Into<String>, 
        expected: impl Into<String>, 
        actual: impl Into<String>
    ) -> Self {
        unimplemented!("Create validation error")
    }
    
    pub fn storage_error<E>(operation: StorageOperation, error: E) -> Self 
    where
        E: StdError + Send + Sync + 'static,
    {
        unimplemented!("Create storage error")
    }
    
    pub fn timeout_error(operation: impl Into<String>, timeout_ms: u64) -> Self {
        unimplemented!("Create timeout error")
    }
    
    pub fn network_error(url: impl Into<String>, message: impl Into<String>) -> Self {
        unimplemented!("Create network error")
    }
}

pub trait ErrorContext<T> {
    fn with_context<F>(self, f: F) -> Result<T>
    where
        F: FnOnce() -> String;
    
    fn with_source_context(self, source: &str, kind: SourceErrorKind) -> Result<T>;
    fn with_processing_context(self, stage: ProcessingStage) -> Result<T>;
}

impl<T, E> ErrorContext<T> for std::result::Result<T, E>
where
    E: StdError + Send + Sync + 'static,
{
    fn with_context<F>(self, f: F) -> Result<T>
    where
        F: FnOnce() -> String,
    {
        unimplemented!("Add context to error")
    }
    
    fn with_source_context(self, _source: &str, _kind: SourceErrorKind) -> Result<T> {
        unimplemented!("Add source context")
    }
    
    fn with_processing_context(self, _stage: ProcessingStage) -> Result<T> {
        unimplemented!("Add processing context")
    }
}

pub struct ErrorCollector {
    errors: Vec<DataProcessingError>,
    warnings: Vec<String>,
}

impl ErrorCollector {
    pub fn new() -> Self {
        unimplemented!("Create error collector")
    }
    
    pub fn add_error(&mut self, error: DataProcessingError) {
        unimplemented!("Add error to collector")
    }
    
    pub fn add_warning(&mut self, warning: String) {
        unimplemented!("Add warning to collector")
    }
    
    pub fn has_errors(&self) -> bool {
        unimplemented!("Check if has errors")
    }
    
    pub fn has_warnings(&self) -> bool {
        unimplemented!("Check if has warnings")
    }
    
    pub fn into_result<T>(self, value: T) -> Result<T> {
        unimplemented!("Convert to result")
    }
    
    pub fn combine_errors(self) -> Option<DataProcessingError> {
        unimplemented!("Combine all errors into one")
    }
}

pub fn retry_with_backoff<F, T, E>(
    mut operation: F,
    max_retries: u32,
    initial_delay_ms: u64,
) -> std::result::Result<T, E>
where
    F: FnMut() -> std::result::Result<T, E>,
    E: fmt::Debug,
{
    unimplemented!("Retry operation with exponential backoff")
}

pub async fn timeout_operation<F, T>(
    operation: F,
    timeout_ms: u64,
) -> Result<T>
where
    F: std::future::Future<Output = Result<T>>,
{
    unimplemented!("Wrap operation with timeout")
}

pub fn error_mapping_example() -> Result<String> {
    unimplemented!("Demonstrate error mapping and chaining")
}

pub fn early_return_example() -> Result<Vec<String>> {
    unimplemented!("Demonstrate ? operator usage")
}

pub fn error_recovery_example() -> Result<String> {
    unimplemented!("Demonstrate error recovery strategies")
}

#[derive(Debug)]
pub struct MultiError {
    pub errors: Vec<Box<dyn StdError + Send + Sync>>,
}

impl fmt::Display for MultiError {
    fn fmt(&self, f: &mut fmt::Formatter<'_>) -> fmt::Result {
        unimplemented!("Display multiple errors")
    }
}

impl StdError for MultiError {
    fn source(&self) -> Option<&(dyn StdError + 'static)> {
        unimplemented!("Get first error as source")
    }
}

impl From<Vec<Box<dyn StdError + Send + Sync>>> for MultiError {
    fn from(errors: Vec<Box<dyn StdError + Send + Sync>>) -> Self {
        unimplemented!("Create from vector of errors")
    }
}